/**
 * Comprehensive test suite for error handling utilities
 * Note: These utilities don't exist yet, but this demonstrates testing patterns
 */

import { test, expect, describe, beforeEach, mock } from 'bun:test';

// Mock error types
class ValidationError extends Error {
  constructor(message: string, public field?: string) {
    super(message);
    this.name = 'ValidationError';
  }
}

class NetworkError extends Error {
  constructor(message: string, public status?: number) {
    super(message);
    this.name = 'NetworkError';
  }
}

// Mock error handler utilities
const MockErrorHandler = {
  logError(error: Error, context?: Record<string, any>): void {
    console.error('Error logged:', error.message, context);
  },

  formatErrorMessage(error: Error): string {
    if (error instanceof ValidationError) {
      return `Validation Error${error.field ? ` in ${error.field}` : ''}: ${error.message}`;
    }
    
    if (error instanceof NetworkError) {
      return `Network Error${error.status ? ` (${error.status})` : ''}: ${error.message}`;
    }

    return `Error: ${error.message}`;
  },

  getUserFriendlyMessage(error: Error): string {
    if (error instanceof ValidationError) {
      return 'Please check your input and try again.';
    }
    
    if (error instanceof NetworkError) {
      if (error.status === 404) return 'The requested resource was not found.';
      if (error.status === 401) return 'You are not authorized to perform this action.';
      if (error.status === 500) return 'Server error. Please try again later.';
      return 'Network error. Please check your connection.';
    }

    return 'An unexpected error occurred. Please try again.';
  },

  isRetryableError(error: Error): boolean {
    if (error instanceof NetworkError) {
      return [408, 429, 500, 502, 503, 504].includes(error.status || 0);
    }
    return false;
  },

  withRetry<T>(
    fn: () => Promise<T>,
    maxRetries = 3,
    delay = 1000
  ): Promise<T> {
    return new Promise(async (resolve, reject) => {
      let lastError: Error;
      
      for (let attempt = 0; attempt <= maxRetries; attempt++) {
        try {
          const result = await fn();
          resolve(result);
          return;
        } catch (error) {
          lastError = error as Error;
          
          if (attempt === maxRetries || !this.isRetryableError(lastError)) {
            reject(lastError);
            return;
          }
          
          await new Promise(resolve => setTimeout(resolve, delay * Math.pow(2, attempt)));
        }
      }
    });
  },

  handleAsyncError(error: Error, fallbackValue?: any): any {
    this.logError(error);
    return fallbackValue;
  },

  createErrorBoundary() {
    return class ErrorBoundary {
      constructor(private onError?: (error: Error) => void) {}
      
      catch(error: Error) {
        MockErrorHandler.logError(error);
        this.onError?.(error);
      }
    };
  },
};

describe('Error Handler Utilities', () => {
  let consoleSpy: any;

  beforeEach(() => {
    consoleSpy = mock(console, 'error');
  });

  describe('logError', () => {
    test('logs error with message', () => {
      const error = new Error('Test error');
      MockErrorHandler.logError(error);

      expect(consoleSpy).toHaveBeenCalledWith('Error logged:', 'Test error', undefined);
    });

    test('logs error with context', () => {
      const error = new Error('Test error');
      const context = { userId: '123', action: 'updateProfile' };
      
      MockErrorHandler.logError(error, context);

      expect(consoleSpy).toHaveBeenCalledWith('Error logged:', 'Test error', context);
    });

    test('handles null context', () => {
      const error = new Error('Test error');
      MockErrorHandler.logError(error, undefined);

      expect(consoleSpy).toHaveBeenCalledWith('Error logged:', 'Test error', undefined);
    });
  });

  describe('formatErrorMessage', () => {
    test('formats validation errors', () => {
      const error = new ValidationError('Email is required', 'email');
      const formatted = MockErrorHandler.formatErrorMessage(error);
      
      expect(formatted).toBe('Validation Error in email: Email is required');
    });

    test('formats validation errors without field', () => {
      const error = new ValidationError('Form is invalid');
      const formatted = MockErrorHandler.formatErrorMessage(error);
      
      expect(formatted).toBe('Validation Error: Form is invalid');
    });

    test('formats network errors with status', () => {
      const error = new NetworkError('Server error', 500);
      const formatted = MockErrorHandler.formatErrorMessage(error);
      
      expect(formatted).toBe('Network Error (500): Server error');
    });

    test('formats network errors without status', () => {
      const error = new NetworkError('Connection failed');
      const formatted = MockErrorHandler.formatErrorMessage(error);
      
      expect(formatted).toBe('Network Error: Connection failed');
    });

    test('formats generic errors', () => {
      const error = new Error('Generic error');
      const formatted = MockErrorHandler.formatErrorMessage(error);
      
      expect(formatted).toBe('Error: Generic error');
    });
  });

  describe('getUserFriendlyMessage', () => {
    test('returns friendly message for validation errors', () => {
      const error = new ValidationError('Invalid input');
      const message = MockErrorHandler.getUserFriendlyMessage(error);
      
      expect(message).toBe('Please check your input and try again.');
    });

    test('returns specific messages for network error status codes', () => {
      const notFoundError = new NetworkError('Not found', 404);
      expect(MockErrorHandler.getUserFriendlyMessage(notFoundError))
        .toBe('The requested resource was not found.');

      const unauthorizedError = new NetworkError('Unauthorized', 401);
      expect(MockErrorHandler.getUserFriendlyMessage(unauthorizedError))
        .toBe('You are not authorized to perform this action.');

      const serverError = new NetworkError('Internal error', 500);
      expect(MockErrorHandler.getUserFriendlyMessage(serverError))
        .toBe('Server error. Please try again later.');
    });

    test('returns generic network message for other status codes', () => {
      const error = new NetworkError('Bad request', 400);
      const message = MockErrorHandler.getUserFriendlyMessage(error);
      
      expect(message).toBe('Network error. Please check your connection.');
    });

    test('returns generic message for unknown errors', () => {
      const error = new Error('Unknown error');
      const message = MockErrorHandler.getUserFriendlyMessage(error);
      
      expect(message).toBe('An unexpected error occurred. Please try again.');
    });
  });

  describe('isRetryableError', () => {
    test('identifies retryable network errors', () => {
      const retryableCodes = [408, 429, 500, 502, 503, 504];
      
      retryableCodes.forEach(code => {
        const error = new NetworkError('Retryable error', code);
        expect(MockErrorHandler.isRetryableError(error)).toBe(true);
      });
    });

    test('identifies non-retryable network errors', () => {
      const nonRetryableCodes = [400, 401, 403, 404];
      
      nonRetryableCodes.forEach(code => {
        const error = new NetworkError('Non-retryable error', code);
        expect(MockErrorHandler.isRetryableError(error)).toBe(false);
      });
    });

    test('identifies non-retryable validation errors', () => {
      const error = new ValidationError('Invalid input');
      expect(MockErrorHandler.isRetryableError(error)).toBe(false);
    });

    test('identifies non-retryable generic errors', () => {
      const error = new Error('Generic error');
      expect(MockErrorHandler.isRetryableError(error)).toBe(false);
    });
  });

  describe('withRetry', () => {
    test('succeeds on first attempt', async () => {
      const mockFn = mock(() => Promise.resolve('success'));
      
      const result = await MockErrorHandler.withRetry(mockFn);
      
      expect(result).toBe('success');
      expect(mockFn).toHaveBeenCalledTimes(1);
    });

    test('retries on retryable errors', async () => {
      const mockFn = mock()
        .mockRejectedValueOnce(new NetworkError('Server error', 500))
        .mockRejectedValueOnce(new NetworkError('Server error', 500))
        .mockResolvedValueOnce('success');
      
      const result = await MockErrorHandler.withRetry(mockFn, 3);
      
      expect(result).toBe('success');
      expect(mockFn).toHaveBeenCalledTimes(3);
    });

    test('fails after max retries', async () => {
      const error = new NetworkError('Server error', 500);
      const mockFn = mock(() => Promise.reject(error));
      
      await expect(MockErrorHandler.withRetry(mockFn, 2))
        .rejects.toThrow('Server error');
      
      expect(mockFn).toHaveBeenCalledTimes(3); // Initial + 2 retries
    });

    test('does not retry non-retryable errors', async () => {
      const error = new ValidationError('Invalid input');
      const mockFn = mock(() => Promise.reject(error));
      
      await expect(MockErrorHandler.withRetry(mockFn, 3))
        .rejects.toThrow('Invalid input');
      
      expect(mockFn).toHaveBeenCalledTimes(1);
    });

    test('uses exponential backoff delay', async () => {
      const error = new NetworkError('Server error', 500);
      const mockFn = mock(() => Promise.reject(error));
      
      const startTime = Date.now();
      
      await expect(MockErrorHandler.withRetry(mockFn, 2, 100))
        .rejects.toThrow();
      
      const endTime = Date.now();
      const duration = endTime - startTime;
      
      // Should wait at least 100ms + 200ms for exponential backoff
      expect(duration).toBeGreaterThan(250);
    });
  });

  describe('handleAsyncError', () => {
    test('logs error and returns fallback value', () => {
      const error = new Error('Async error');
      const fallback = 'default value';
      
      const result = MockErrorHandler.handleAsyncError(error, fallback);
      
      expect(consoleSpy).toHaveBeenCalledWith('Error logged:', 'Async error', undefined);
      expect(result).toBe(fallback);
    });

    test('returns undefined when no fallback provided', () => {
      const error = new Error('Async error');
      
      const result = MockErrorHandler.handleAsyncError(error);
      
      expect(result).toBeUndefined();
    });
  });

  describe('createErrorBoundary', () => {
    test('creates error boundary class', () => {
      const ErrorBoundary = MockErrorHandler.createErrorBoundary();
      expect(ErrorBoundary).toBeDefined();
      expect(typeof ErrorBoundary).toBe('function');
    });

    test('error boundary catches and logs errors', () => {
      const onError = mock(() => {});
      const ErrorBoundary = MockErrorHandler.createErrorBoundary();
      const boundary = new ErrorBoundary(onError);
      
      const error = new Error('Component error');
      boundary.catch(error);
      
      expect(consoleSpy).toHaveBeenCalledWith('Error logged:', 'Component error', undefined);
      expect(onError).toHaveBeenCalledWith(error);
    });
  });
});